Workbook

Sheet Resumen
A1: RESUMEN DEL PRESUPUESTO
A2: Tienda Spare Parts — implementación completa de local comercial · Huancayo, Junín
A4: Área del local (m2) | B4: 177.03
A5: Área de ventas (m2) | B5: 139.78
A6: Mezanine (m2) | B6: 6.22
A7: Inicio de obra (programado) | B7: 02/12/2024
A8: Fin de obra (programado) | B8: 01/03/2025
A9: Plazo (días laborables) | B9: 74
A11: Item | B11: Especialidad | C11: Monto S/ | D11: % del CD
A12: 01 | B12: OBRAS PROVISIONALES Y TRABAJOS PRELIMINARES | C12: =Presupuesto!F5 | D12: =C12/C21
A13: 02 | B13: REMODELACIÓN DE MUROS Y OBRAS CIVILES | C13: =Presupuesto!F14 | D13: =C13/C21
A14: 03 | B14: MEZANINE METÁLICO Y ESCALERA | C14: =Presupuesto!F22 | D14: =C14/C21
A15: 04 | B15: ARQUITECTURA Y ACABADOS | C15: =Presupuesto!F29 | D15: =C15/C21
A16: 05 | B16: FACHADA Y LETRERO | C16: =Presupuesto!F42 | D16: =C16/C21
A17: 06 | B17: MOBILIARIO DE EXHIBICIÓN (DISEÑO PROPIO) | C17: =Presupuesto!F50 | D17: =C17/C21
A18: 07 | B18: INSTALACIONES ELÉCTRICAS (SEGÚN PLANO IE) | C18: =Presupuesto!F60 | D18: =C18/C21
A19: 08 | B19: INSTALACIONES SANITARIAS | C19: =Presupuesto!F72 | D19: =C19/C21
A20: 09 | B20: VARIOS | C20: =Presupuesto!F76 | D20: =C20/C21
B21: COSTO DIRECTO | C21: =SUM(C12:C20)
B22: Gastos generales (10%) | C22: =ROUND(C21*0.10,2)
B23: Utilidad (8%) | C23: =ROUND(C21*0.08,2)
B24: SUBTOTAL | C24: =C21+C22+C23
B25: IGV (18%) | C25: =ROUND(C24*0.18,2)
B26: PRESUPUESTO TOTAL | C26: =C24+C25
B27: Costo directo por m2 de local | C27: =C21/B4
B28: Costo total por m2 de local | C28: =C26/B4
A31: Nota: metrados tomados de los planos de obra y precios unitarios de mercado 2024-2025, sin IGV, en especificaciones económicas de cadena (los mismos materiales de los renders en su línea comercial). Plazo programado de lunes a sábado, con los feriados nacionales.

Sheet Presupuesto
A1: PRESUPUESTO DE OBRA — IMPLEMENTACIÓN DE LA TIENDA SPARE PARTS (HUANCAYO)
A2: Estructura tipo S10 · Metrados de los planos de obra · Especificaciones económicas de cadena · Precios de mercado 2024-2025, sin IGV · 2M MICON S.A.C. · Jashira Illescas Rodriguez
A4: Item | B4: Descripción | C4: Und. | D4: Metrado | E4: Precio S/ | F4: Parcial S/ | G4: Fuente del metrado
A5: 01 | B5: OBRAS PROVISIONALES Y TRABAJOS PRELIMINARES | F5: =SUMIFS(F6:F13,D6:D13,"<>")
A6: 01.01 | B6: Movilización y desmovilización de equipos y herramientas | C6: glb | D6: 1 | E6: 1500 | F6: =ROUND(D6*E6,2) | G6: Global
A7: 01.02 | B7: Flete de mobiliario y materiales Lima - Huancayo (un viaje consolidado) | C7: glb | D7: 1 | E7: 2400 | F7: =ROUND(D7*E7,2) | G7: 1 viaje de camión
A8: 01.03 | B8: Protección de fachada y cerco provisional con paneles h=2.40 m | C8: m | D8: 9.07 | E8: 45 | F8: =ROUND(D8*E8,2) | G8: Fachada (modelo)
A9: 01.04 | B9: Almacén y caseta provisional dentro del local | C9: glb | D9: 1 | E9: 700 | F9: =ROUND(D9*E9,2) | G9: Global
A10: 01.05 | B10: Trazo, nivelación y replanteo | C10: m2 | D10: 177.03 | E10: 2.5 | F10: =ROUND(D10*E10,2) | G10: Área del local (modelo)
A11: 01.06 | B11: Seguridad y salud en obra (EPP, señalización, extintores) | C11: glb | D11: 1 | E11: 1800 | F11: =ROUND(D11*E11,2) | G11: Global
A12: 01.07 | B12: Desmontaje de instalaciones y elementos existentes | C12: glb | D12: 1 | E12: 1200 | F12: =ROUND(D12*E12,2) | G12: Levantamiento
A13: 01.08 | B13: Eliminación de desmonte con volquete (D = 10 km) | C13: m3 | D13: 12 | E13: 55 | F13: =ROUND(D13*E13,2) | G13: Demoliciones + picados
A14: 02 | B14: REMODELACIÓN DE MUROS Y OBRAS CIVILES | F14: =SUMIFS(F15:F21,D15:D21,"<>")
A15: 02.01 | B15: Demolición de tabiques existentes | C15: m2 | D15: 16 | E15: 32 | F15: =ROUND(D15*E15,2) | G15: Levantamiento
A16: 02.02 | B16: Picado de muros y piso para canalizaciones | C16: m | D16: 120 | E16: 11 | F16: =ROUND(D16*E16,2) | G16: Recorridos de IIEE e IISS
A17: 02.03 | B17: Muro de ladrillo KK 18 huecos en SS.HH., soga, mezcla 1:4 | C17: m2 | D17: 4.32 | E17: =APU!$F$18 | F17: =ROUND(D17*E17,2) | G17: Muros de SS.HH. (modelo)
A18: 02.04 | B18: Tarrajeo frotachado en muros, mezcla 1:5 | C18: m2 | D18: 317.39 | E18: =APU!$F$36 | F18: =ROUND(D18*E18,2) | G18: Caras interiores (modelo)
A19: 02.05 | B19: Tarrajeo de columnas existentes | C19: m2 | D19: 83.63 | E19: 38 | F19: =ROUND(D19*E19,2) | G19: 20 columnas (modelo)
A20: 02.06 | B20: Nivelación del piso existente con mortero autonivelante (resanes y juntas) | C20: m2 | D20: 139.78 | E20: 14 | F20: =ROUND(D20*E20,2) | G20: Área de ventas (modelo)
A21: 02.07 | B21: Sardinel y resanes en el frente de fachada | C21: m | D21: 9.07 | E21: 55 | F21: =ROUND(D21*E21,2) | G21: Fachada (modelo)
A22: 03 | B22: MEZANINE METÁLICO Y ESCALERA | F22: =SUMIFS(F23:F28,D23:D28,"<>")
A23: 03.01 | B23: Columnas de tubo LAC 4"x4"x3 mm con plancha base y anclaje químico | C23: und | D23: 3 | E23: 700 | F23: =ROUND(D23*E23,2) | G23: Mezanine (modelo)
A24: 03.02 | B24: Vigas y viguetas de acero con pintura anticorrosiva | C24: kg | D24: 220 | E24: 12.5 | F24: =ROUND(D24*E24,2) | G24: 20 m de perfiles (modelo)
A25: 03.03 | B25: Losa colaborante: placa de acero + concreto f'c=210 kg/cm2, e = 10 cm | C25: m2 | D25: 6.22 | E25: 175 | F25: =ROUND(D25*E25,2) | G25: Mezanine (modelo)
A26: 03.04 | B26: Escalera metálica de 12 pasos con peldaños de plancha estriada | C26: und | D26: 1 | E26: 3000 | F26: =ROUND(D26*E26,2) | G26: Escalera (plano)
A27: 03.05 | B27: Baranda de vidrio templado 8 mm con pasamanos de acero | C27: m | D27: 2.5 | E27: 360 | F27: =ROUND(D27*E27,2) | G27: Borde del mezanine (modelo)
A28: 03.06 | B28: Franja de ACM 3 mm turquesa en el borde del mezanine | C28: m2 | D28: 1.6 | E28: 185 | F28: =ROUND(D28*E28,2) | G28: Borde del mezanine (modelo)
A29: 04 | B29: ARQUITECTURA Y ACABADOS | F29: =SUMIFS(F30:F41,D30:D41,"<>")
A30: 04.01 | B30: Piso SPC 4 mm tipo madera, tránsito comercial, con contrazócalo | C30: m2 | D30: 146 | E30: =APU!$F$52 | F30: =ROUND(D30*E30,2) | G30: Ventas + mezanine (modelo)
A31: 04.02 | B31: Cerámico antideslizante 45x45 cm en pisos de SS.HH. | C31: m2 | D31: 5.74 | E31: 68 | F31: =ROUND(D31*E31,2) | G31: SS.HH. (modelo)
A32: 04.03 | B32: Enchape de cerámico 30x60 cm en paredes de SS.HH. h = 2.10 m | C32: m2 | D32: 16.17 | E32: 66 | F32: =ROUND(D32*E32,2) | G32: SS.HH. (modelo)
A33: 04.04 | B33: Pintura látex negro mate en techo y muros altos | C33: m2 | D33: 250.22 | E33: 12.5 | F33: =ROUND(D33*E33,2) | G33: Techo + franja alta (modelo)
A34: 04.05 | B34: Pintura látex lavable en muros (2 manos) | C34: m2 | D34: 144.05 | E34: 11 | F34: =ROUND(D34*E34,2) | G34: Muros bajos y almacén (modelo)
A35: 04.06 | B35: Pintura látex negro mate en columnas | C35: m2 | D35: 83.63 | E35: 12.5 | F35: =ROUND(D35*E35,2) | G35: 20 columnas (modelo)
A36: 04.07 | B36: Panel perforado (pegboard) de MDF melamínico con accesorios | C36: m2 | D36: 35.01 | E36: 125 | F36: =ROUND(D36*E36,2) | G36: Tras las repisas (modelo)
A37: 04.08 | B37: Muro verde artificial y listones de madera (letrero de marca) | C37: m2 | D37: 9.47 | E37: 230 | F37: =ROUND(D37*E37,2) | G37: Muro C (modelo)
A38: 04.09 | B38: Revestimiento de listones de MDF enchapado en el muro de la caja | C38: m2 | D38: 5.1 | E38: 160 | F38: =ROUND(D38*E38,2) | G38: Muro del eje 2 (modelo)
A39: 04.10 | B39: Puertas contraplacadas de SS.HH. y almacén, con marco y cerrajería | C39: und | D39: 3 | E39: 480 | F39: =ROUND(D39*E39,2) | G39: Plano de distribución
A40: 04.11 | B40: Aparatos sanitarios de línea económica: inodoro, lavatorio y grifería | C40: jgo | D40: 2 | E40: 560 | F40: =ROUND(D40*E40,2) | G40: 2 SS.HH. (plano)
A41: 04.12 | B41: Accesorios de SS.HH. (espejo, dispensadores y barras) | C41: jgo | D41: 2 | E41: 190 | F41: =ROUND(D41*E41,2) | G41: 2 SS.HH. (plano)
...

Sheet APU
A1: ANÁLISIS DE PRECIOS UNITARIOS (muestra)
A2: Costo hora-hombre con leyes sociales, régimen de construcción civil 2024-2025
A4: APU1 · Muro de ladrillo KK 18 huecos en SS.HH., soga, mezcla 1:4
A5: Rendimiento: 9 m2/día · Unidad: m2
A6: Descripción | B6: Und. | C6: Cuadrilla | D6: Cantidad | E6: Precio S/ | F6: Parcial S/
A7: Mano de obra
A8: Capataz | B8: hh | C8: 0.1 | D8: =ROUND(C8*8/9.0,4) | E8: 31.5 | F8: =ROUND(D8*E8,2)
A9: Operario | B9: hh | C9: 1 | D9: =ROUND(C9*8/9.0,4) | E9: 28.6 | F9: =ROUND(D9*E9,2)
A10: Peón | B10: hh | C10: 0.5 | D10: =ROUND(C10*8/9.0,4) | E10: 20.8 | F10: =ROUND(D10*E10,2)
A11: Materiales
A12: Ladrillo KK 18 huecos 9x13x23 cm | B12: und | D12: 39 | E12: 1.15 | F12: =ROUND(D12*E12,2)
A13: Cemento Portland tipo I (42.5 kg) | B13: bls | D13: 0.21 | E13: 29.5 | F13: =ROUND(D13*E13,2)
A14: Arena gruesa | B14: m3 | D14: 0.03 | E14: 70 | F14: =ROUND(D14*E14,2)
A15: Agua puesta en obra | B15: m3 | D15: 0.007 | E15: 8 | F15: =ROUND(D15*E15,2)
A16: Equipos y herramientas
A17: Herramientas manuales | B17: %MO | D17: 0.03 | F17: =ROUND(D17*SUM(F8:F10),2)
E18: COSTO UNITARIO | F18: =SUM(F8:F10)+SUM(F12:F15)+SUM(F17:F17)
A21: APU2 · Tarrajeo frotachado en muros, mezcla 1:5
A22: Rendimiento: 15 m2/día · Unidad: m2
A23: Descripción | B23: Und. | C23: Cuadrilla | D23: Cantidad | E23: Precio S/ | F23: Parcial S/
A24: Mano de obra
A25: Capataz | B25: hh | C25: 0.1 | D25: =ROUND(C25*8/15.0,4) | E25: 31.5 | F25: =ROUND(D25*E25,2)
A26: Operario | B26: hh | C26: 1 | D26: =ROUND(C26*8/15.0,4) | E26: 28.6 | F26: =ROUND(D26*E26,2)
A27: Peón | B27: hh | C27: 0.5 | D27: =ROUND(C27*8/15.0,4) | E27: 20.8 | F27: =ROUND(D27*E27,2)
A28: Materiales
A29: Cemento Portland tipo I (42.5 kg) | B29: bls | D29: 0.105 | E29: 29.5 | F29: =ROUND(D29*E29,2)
A30: Arena fina | B30: m3 | D30: 0.018 | E30: 75 | F30: =ROUND(D30*E30,2)
A31: Agua puesta en obra | B31: m3 | D31: 0.005 | E31: 8 | F31: =ROUND(D31*E31,2)
A32: Regla de madera | B32: p2 | D32: 0.02 | E32: 6 | F32: =ROUND(D32*E32,2)
A33: Equipos y herramientas
A34: Herramientas manuales | B34: %MO | D34: 0.03 | F34: =ROUND(D34*SUM(F25:F27),2)
A35: Andamio metálico (muros de 4.70 m) | B35: día | D35: 0.03 | E35: 8.5 | F35: =ROUND(D35*E35,2)
E36: COSTO UNITARIO | F36: =SUM(F25:F27)+SUM(F29:F32)+SUM(F34:F35)
A39: APU3 · Piso SPC 4 mm tipo madera, tránsito comercial, con manta y contrazócalo
A40: Rendimiento: 35 m2/día · Unidad: m2
A41: Descripción | B41: Und. | C41: Cuadrilla | D41: Cantidad | E41: Precio S/ | F41: Parcial S/
A42: Mano de obra
A43: Operario | B43: hh | C43: 1 | D43: =ROUND(C43*8/35.0,4) | E43: 28.6 | F43: =ROUND(D43*E43,2)
A44: Oficial | B44: hh | C44: 0.5 | D44: =ROUND(C44*8/35.0,4) | E44: 23.1 | F44: =ROUND(D44*E44,2)
A45: Materiales
...

Sheet Metrados
A1: METRADOS DEL MODELO
A2: Calculados desde la geometría leída de los planos de distribución e IIEE (tienda_fuente.py)
A4: Concepto | B4: Valor | C4: Und.
A5: Área del local (sin el pasadizo de la vivienda) | B5: 177.03 | C5: m2
A6: Área de ventas (piso SPC) | B6: 139.78 | C6: m2
A7: Mezanine (oficina) | B7: 6.22 | C7: m2
A8: SS.HH. (2) | B8: 5.74 | C8: m2
A9: Muros nuevos de SS.HH. | B9: 4.32 | C9: m2
A10: Tarrajeo de muros | B10: 317.39 | C10: m2
A11: Tarrajeo de columnas | B11: 83.63 | C11: m2
A12: Pintura negra (techo y muros altos) | B12: 250.22 | C12: m2
A13: Pintura látex (muros bajos y almacén) | B13: 144.05 | C13: m2
A14: Panel perforado | B14: 35.01 | C14: m2
A15: Muro verde y listones | B15: 9.47 | C15: m2
A16: ACM negro | B16: 12.29 | C16: m2
... A30: Tarrajeo · Muro del pasadizo, cara del almacén (4.83 x 4.7 m) | B30: 22.7 | C30: m2

Sheet Cronograma
A1: CRONOGRAMA DE OBRA — calendario de lunes a sábado con feriados nacionales
A2: Mismo plan que Cronograma_SpareParts_Huancayo.xml (MS Project). Las barras se dibujan con formato condicional.
G3: 45628 | H3: 45635 | I3: 45642 | J3: 45649 | K3: 45656 | L3: 45663 | M3: 45670 | N3: 45677 | O3: 45684 | P3: 45691 | Q3: 45698 | R3: 45705 | S3: 45712
A4: Id | B4: Tarea | C4: Inicio | D4: Fin | E4: Días lab. | F4: Costo directo S/ | G4: S1 | H4: S2 | I4: S3 | J4: S4 | K4: S5 | L4: S6 | M4: S7 | N4: S8 | O4: S9 | P4: S10 | Q4: S11 | R4: S12 | S4: S13
A5: 1 | B5: Inicio de obra (entrega del local) | C5: 45628 | D5: 45628 | E5: 0 | F5: 0
A6: 2 | B6: OBRAS PRELIMINARES | C6: 45628 | D6: 45637 | E6: 8
A7: 3 | B7: Movilización, protección de fachada e instalaciones provisionales | C7: 45628 | D7: 45630 | E7: 3 | F7: 1858.15
A8: 4 | B8: Levantamiento, trazo y replanteo | C8: 45631 | D8: 45632 | E8: 2 | F8: 442.58
A9: 5 | B9: Desmontaje de instalaciones y elementos existentes | C9: 45633 | D9: 45637 | E9: 3 | F9: 1200
A10: 6 | B10: REMODELACIÓN DE MUROS | C10: 45638 | D10: 45668 | E10: 25
A11: 7 | B11: Demolición de tabiques y picado para canalizaciones | C11: 45638 | D11: 45643 | E11: 5 | F11: 2492
A12: 8 | B12: Muros de ladrillo de SS.HH. | C12: 45644 | D12: 45647 | E12: 4 | F12: 396.53
A13: 9 | B13: Tarrajeo de muros y columnas | C13: 45646 | D13: 45668 | E13: 18 | F13: 12071.21
A14: 10 | B14: Nivelación del piso existente | C14: 45660 | D14: 45664 | E14: 4 | F14: 1956.92
A15: 11 | B15: MEZANINE Y ESCALERA METÁLICA | C15: 45649 | D15: 45665 | E15: 13
A16: 12 | B16: Columnas metálicas del mezanine (anclaje) | C16: 45649 | D16: 45650 | E16: 2 | F16: 2100
A17: 13 | B17: Vigas y viguetas metálicas | C17: 45652 | D17: 45656 | E17: 4 | F17: 2750
A18: 14 | B18: Losa colaborante del mezanine | C18: 45657 | D18: 45660 | E18: 3 | F18: 1088.5
A19: 15 | B19: Escalera metálica de 12 pasos | C19: 45657 | D19: 45661 | E19: 4 | F19: 3000
A20: 16 | B20: Baranda de vidrio y franja turquesa | C20: 45663 | D20: 45665 | E20: 3 | F20: 1196
A21: 17 | B21: INSTALACIONES | C21: 45640 | D21: 45675 | E21: 29
A22: 18 | B22: Instalaciones sanitarias de SS.HH. | C22: 45645 | D22: 45650 | E22: 5 | F22: 1666
A23: 19 | B23: IIEE: tuberías, cajas y canalizaciones | C23: 45640 | D23: 45649 | E23: 8 | F23: 2723.4
A24: 20 | B24: IIEE: cableado, tablero y pozo a tierra | C24: 45670 | D24: 45675 | E24: 6 | F24: 4953.6
A25: 21 | B25: ACABADOS | C25: 45670 | D25: 45698 | E25: 25
A26: 22 | B26: Pintura negra en techo y muros altos | C26: 45670 | D26: 45678 | E26: 8 | F26: 3127.75
A27: 23 | B27: Porcelanato en pisos y paredes de SS.HH. | C27: 45670 | D27: 45674 | E27: 5 | F27: 1457.54
A28: 24 | B28: Piso SPC tipo madera | C28: 45679 | D28: 45685 | E28: 6 | F28: 9516.28
A29: 25 | B29: Pintura látex en muros y negro en columnas | C29: 45679 | D29: 45687 | E29: 8 | F29: 2629.93
A30: 26 | B30: Panel perforado, muro verde y listones | C30: 45688 | D30: 45698 | E30: 9 | F30: 7370.35
A31: 27 | B31: Puertas y aparatos sanitarios | C31: 45675 | D31: 45678 | E31: 3 | F31: 2940
A32: 28 | B32: FACHADA Y LETRERO | C32: 45652 | D32: 45680 | E32: 24
A33: 29 | B33: Estructura metálica de fachada | C33: 45652 | D33: 45657 | E33: 5 | F33: 4178.85
A34: 30 | B34: Revestimiento ACM negro y turquesa | C34: 45659 | D34: 45665 | E34: 6 | F34: 3568.9
A35: 31 | B35: Mampara y puerta de vidrio templado | C35: 45666 | D35: 45671 | E35: 5 | F35: 7299.85
A36: 32 | B36: Letrero luminoso (logo y letras) | C36: 45677 | D36: 45680 | E36: 4 | F36: 6650
A37: 33 | B37: MOBILIARIO E ILUMINACIÓN | C37: 45633 | D37: 45709 | E37: 63
A38: 34 | B38: Fabricación del mobiliario en taller y traslado | C38: 45633 | D38: 45688 | E38: 45 | F38: 15131.25
A39: 35 | B39: Instalación del mobiliario de exhibición y caja | C39: 45699 | D39: 45709 | E39: 10 | F39: 7506.25
A40: 36 | B40: Luminarias suspendidas y artefactos | C40: 45688 | D40: 45693 | E40: 5 | F40: 5825
...

Sheet Curva S
A1: CURVA S — AVANCE PROGRAMADO DEL COSTO DIRECTO
A2: Costo semanal = costo de cada tarea repartido en sus días laborables
A4: Semana | B4: Inicio | C4: Costo semanal S/ | D4: Acumulado S/ | E4: % acumulado
A5: 1 | B5: 45628 | C5: 3182.93 | D5: =C5 | E5: =D5/Presupuesto!F80
A6: 2 | B6: 45635 | C6: 4438.5 | D6: =D5+C6 | E6: =D6/Presupuesto!F80
A7: 3 | B7: 45642 | C7: 7940.17 | D7: =D6+C7 | E7: =D7/Presupuesto!F80
A8: 4 | B8: 45649 | C8: 12832.62 | D8: =D7+C8 | E8: =D8/Presupuesto!F80
A9: 5 | B9: 45656 | C9: 14366.44 | D9: =D8+C9 | E9: =D9/Presupuesto!F80
A10: 6 | B10: 45663 | C10: 14526 | D10: =D9+C10 | E10: =D10/Presupuesto!F80
A11: 7 | B11: 45670 | C11: 14820.34 | D11: =D10+C11 | E11: =D11/Presupuesto!F80
A12: 8 | B12: 45677 | C12: 19214.54 | D12: =D11+C12 | E12: =D12/Presupuesto!F80
A13: 9 | B13: 45684 | C13: 10282.11 | D13: =D12+C13 | E13: =D13/Presupuesto!F80
A14: 10 | B14: 45691 | C14: 11354.51 | D14: =D13+C14 | E14: =D14/Presupuesto!F80
A15: 11 | B15: 45698 | C15: 4718 | D15: =D14+C15 | E15: =D15/Presupuesto!F80
A16: 12 | B16: 45705 | C16: 4212.09 | D16: =D15+C16 | E16: =D16/Presupuesto!F80
A17: 13 | B17: 45712 | C17: 1686.72 | D17: =D16+C17 | E17: =D17/Presupuesto!F80
